Workbook

Sheet Balance General
A1: BALANCE GENERAL [BALANCE SHEET] | C1: Ratios
A4: Liquidez, Miden la capacidad de la empresa para cubrir compromisos a corto plazo, un ratio 1:1 es considerado como normal, un ratio 2:0 o mayor es considerado como bueno. [Activo Circulante/Pasivo Circulante] | C4: Liquidez | D4: =B25/H24 -> 2.7106978
A6: Gestion del Activo, mide la eficiencia de la empresa en su Rotacion del Activo [Ventas/Activo Total], en su inventario [360/(Costo de Ventas/Inventario)], en sus cuentas por cobrar [360/(Ventas/Cuentas por Cobrar)] y en sus cuentas por pagar [360/(Costo de Ventas/Cuentas por Pagar)]. | C6: Rotacion del Activo | D6: ='Estado de Resultados'!N3/'Balance General'!C91 -> #DIV/0!
C7: Dias de Inventario | D7: =360/('Estado de Resultados'!N4/C24) -> #DIV/0!
C8: Dias de Cuentas por Cobrar | D8: =360/('Estado de Resultados'!N3/C20) -> #DIV/0!
C9: Dias de Cuentas por Pagar | D9: =360/('Estado de Resultados'!N4/I20) -> #DIV/0!
A10: Apalancamiento o Endeudamiento, Si la deuda es mas alta, el nivel de Riesgo sera Mayor, por lo tanto la empresa tendra mejor Rendimiento [Pasivo Total/Activo Total] | C10: Endeudamiento y Rendimiento | D10: =SUM(I24,I26)/C91 -> #DIV/0!
A12: DeudaCapital, Si el porcentaje es mayor al 100% los acreedores aportan mas que los accionistas. [Pasivo Total/Capital Contable] | C12: Deuda y Capital | D12: =SUM(I24,I26)/I76 -> #DIV/0!
A14: Rentabilidad, miden la eficiencia en la operatividad de la empresa. Rendimiento sobre Activos [Utilidad Neta/Activos Totales], DUPONT, lo que gano por cada peso [(Ventas/Activo Total)*(Utilidad Neta/Ventas)] | C14: ROA | D14: ='Estado de Resultados'!N20/C91 -> #DIV/0!
C15: DUPONT | D15: =('Estado de Resultados'!N3/C91)*('Estado de Resultados'!N20/'Estado de Resultados'!N3) -> #DIV/0!
E17: ANALISIS VERTICAL | F17: ANALISIS HORIZONTAL | K17: ANALISIS VERTICAL | L17: ANALISIS HORIZONTAL
A18: ACTIVOS [ASSETS] | B18: INICIAL | C18: MES ACTUAL | D18: MES ANTERIOR | E18: PORCENTAJE DEL MES ACTUAL | F18: INCREMENTO DEL MES ACTUAL | G18: PASIVOS Y CAPITAL CONTABLE [LIABILITIES & EQUITY] | H18: INICIAL | I18: MES ACTUAL | J18: MES ANTERIOR | K18: PORCENTAJE DEL MES ACTUAL | L18: INCREMENTO DEL MES ACTUAL
A19: Efectivo [Cash] | B19: 0 | C19: 0 | D19: 0 | E19: =C19/$C$91 -> #DIV/0! | F19: =((C19/D19)-1) -> #DIV/0! | G19: Proveedores [Suppliers] | H19: 0 | I19: 0 | J19: 0 | K19: =I19/$I$27 -> #DIV/0! | L19: =((I19/J19)-1) -> #DIV/0!
A20: Cuentas por Cobrar [Accounts Receivable] | B20: 0 | C20: 0 | D20: 0 | E20: =C20/$C$91 -> #DIV/0! | F20: =((C20/D20)-1) -> #DIV/0! | G20: Cuentas por Pagar [Accounts Payable] | H20: 12888.6 | I20: 0 | J20: 0 | K20: =I20/$I$27 -> #DIV/0! | L20: =((I20/J20)-1) -> #DIV/0!
A21: Gastos Anticipados [Prepaid Expenses] | B21: 0 | C21: 0 | D21: 0 | E21: =C21/$C$91 -> #DIV/0! | F21: =((C21/D21)-1) -> #DIV/0! | G21: Credito a Corto Plazo [Current Portion of Debt] | I21: 0 | J21: 0 | K21: =I21/$I$27 -> #DIV/0! | L21: =((I21/J21)-1) -> #DIV/0!
A22: Inventario [Inventory] | C22: 0 | D22: 0 | E22: =C22/$C$91 -> #DIV/0! | F22: =((C22/D22)-1) -> #DIV/0! | G22: Impuesto a la Utilidad ISR [Income Taxes Payable] | H22: 0 | I22: 0 | J22: 0 | K22: =I22/$I$27 -> #DIV/0! | L22: =((I22/J22)-1) -> #DIV/0!
A23: Inventario de Materias Primas [Raw Material] | B23: 27434.22 | C23: 0 | D23: 0 | E23: =C23/$C$91 -> #DIV/0! | F23: =((C23/D23)-1) -> #DIV/0! | G23: Beneficios a Empleados [Accrued Expenses] | H23: 0 | I23: 0 | J23: 0 | K23: =I23/$I$27 -> #DIV/0! | L23: =((I23/J23)-1) -> #DIV/0!
A24: Inventario de Productos Terminados [Finished Goods] | B24: 7502.88 | C24: 0 | D24: 0 | E24: =C24/$C$91 -> #DIV/0! | F24: =((C24/D24)-1) -> #DIV/0! | G24: Total De Pasivo Circulante[Current Liabilities] | H24: =SUM(H19:H23) -> 12888.6 | I24: 0 | J24: 0 | K24: =SUM(K19:K23) -> #DIV/0! | L24: =((I24/J24)-1) -> #DIV/0!
A25: Total De Activo Circulante [Current Assets] | B25: =SUM(B19:B24) -> 34937.1 | C25: 0 | D25: 0 | E25: =SUM(E19:E24) -> #DIV/0! | F25: =((C25/D25)-1) -> #DIV/0! | I25: 0 | J25: 0
G26: Credito a Largo Plazo[Long Term Debt] | I26: 0 | J26: 0 | K26: =I26/I27 -> #DIV/0! | L26: =((I26/J26)-1) -> #DIV/0!
A27: Otros Activos [Other Assets] | B27: 12888.6 | C27: 0 | D27: 0 | E27: =C27/C91 -> #DIV/0! | F27: =((C27/D27)-1) -> #DIV/0! | G27: Total de Pasivo [Total Liabilities] | H27: =SUM(H24,H26) -> 12888.6 | I27: 0 | J27: 0 | K27: =SUM(K24,K26) -> #DIV/0!
G28: Capital Contable [Capital Stock] | H28: 95707.38 | I28: 0 | J28: 0 | K28: =I28/$I$30 -> #DIV/0! | L28: =((I28/J28)-1) -> #DIV/0!
A29: Activo Fijo [Fixed Assets] | G29: Ganancias Retenidas [Retained Earnings] | H29: 0 | I29: 0 | J29: 0 | K29: =I29/$I$30 -> #DIV/0! | L29: =((I29/J29)-1) -> #DIV/0!
A30: Pincel Grande | B30: 39 | C30: 0 | D30: 0 | E30: =C30/$C$91 -> #DIV/0! | F30: =((C30/D30)-1) -> #DIV/0! | G30: Capital de los Accionistas [Shareholder´s Equity] | H30: =SUM(H28:H29) -> 95707.38 | I30: 0 | J30: 0 | K30: =SUM(K28:K29) -> #DIV/0! | L30: =((I30/J30)-1) -> #DIV/0!
A31: Pincel Chico | B31: 39 | C31: 0 | D31: 0 | E31: =C31/$C$91 -> #DIV/0! | F31: =((C31/D31)-1) -> #DIV/0!
A32: Bolígrafo | B32: 89 | C32: 0 | D32: 0 | E32: =C32/$C$91 -> #DIV/0! | F32: =((C32/D32)-1) -> #DIV/0! | G32: Total de Pasivo y Capital [Total Liabilities & Equity] | H32: =SUM(H27,H30) -> 108595.98 | I32: 0 | J32: 0 | K32: =(K24+K30) -> #DIV/0! | L32: =((I32/J32)-1) -> #DIV/0!
A33: Regla Profesional | B33: 499 | C33: 0 | D33: 0 | E33: =C33/$C$91 -> #DIV/0! | F33: =((C33/D33)-1) -> #DIV/0!
A34: Tijera | B34: 90 | C34: 0 | D34: 0 | E34: =C34/$C$91 -> #DIV/0! | F34: =((C34/D34)-1) -> #DIV/0!
A35: Cutter | B35: 70 | C35: 0 | D35: 0 | E35: =C35/$C$91 -> #DIV/0! | F35: =((C35/D35)-1) -> #DIV/0!
A36: Pinza Ponchadora | B36: 249 | C36: 0 | D36: 0 | E36: =C36/$C$91 -> #DIV/0! | F36: =((C36/D36)-1) -> #DIV/0!
A37: Pistola para Silicon | B37: 139 | C37: 0 | D37: 0 | E37: =C37/$C$91 -> #DIV/0! | F37: =((C37/D37)-1) -> #DIV/0!
A38: Cautin | B38: 379 | C38: 0 | D38: 0 | E38: =C38/$C$91 -> #DIV/0! | F38: =((C38/D38)-1) -> #DIV/0!
A39: Alicate | B39: 250 | C39: 0 | D39: 0 | E39: =C39/$C$91 -> #DIV/0! | F39: =((C39/D39)-1) -> #DIV/0!
A40: Cortador de Vidrio | B40: 190 | C40: 0 | D40: 0 | E40: =C40/$C$91 -> #DIV/0! | F40: =((C40/D40)-1) -> #DIV/0!
A41: Maquina de Coser | B41: 1500 | C41: 0 | D41: 0 | E41: =C41/$C$91 -> #DIV/0! | F41: =((C41/D41)-1) -> #DIV/0!
A42: Mini Sierra | B42: 896.17 | C42: 0 | D42: 0 | E42: =C42/$C$91 -> #DIV/0! | F42: =((C42/D42)-1) -> #DIV/0!
A43: Molde caldero | B43: 699.75 | C43: 0 | D43: 0 | E43: =C43/$C$91 -> #DIV/0! | F43: =((C43/D43)-1) -> #DIV/0!
A44: Molde Vela | B44: 108.54 | C44: 0 | D44: 0 | E44: =C44/$C$91 -> #DIV/0! | F44: =((C44/D44)-1) -> #DIV/0!
... A89: Depreciacion[Accumulated Depreciation] | B89: 0 | C89: 0 | D89: 0 | E89: =C89/$C$91 -> #DIV/0! | F89: =((C89/D89)-1) -> #DIV/0!
A90: Total De Activo Fijo [Net Fixed Assets] | B90: =SUM(B30:B88)-B89 -> 60770.28 | C90: 0 | D90: 0 | E90: =SUM(E76:E89) -> #DIV/0! | F90: =((C90/D90)-1) -> #DIV/0!
...

Sheet Estado de Resultados
Q1: ANALISIS VERTICAL | R1: ANALISIS HORIZONTAL
A2: ESTADO DE RESULTADOS [INCOME STATEMENT] | B2: PROYECCION INICIAL | C2: MES ACTUAL | D2: MES ANTERIOR | E2: MES ANTERIOR | F2: MES ANTERIOR | G2: MES ANTERIOR | H2: MES ANTERIOR | I2: MES ANTERIOR | J2: MES ANTERIOR | K2: MES ANTERIOR | L2: MES ANTERIOR | M2: MES ANTERIOR | N2: MES ANTERIOR | O2: MES ANTERIOR | P2: MES ANTERIOR | Q2: PORCENTAJE (proyeccion inicial) | R2: INCREMENTO (desde la proyeccion hasta el mes de gananciasl)
A3: Ventas Netas [Net Sales] Unidades Previstas a Vender X Precio de Venta | B3: 44949 | C3: 44949 | D3: 44949 | E3: 44949 | F3: 44949 | G3: 44949 | H3: 44949 | I3: 44949 | J3: 44949 | K3: 44949 | L3: 44949 | M3: 44949 | N3: 44949 | O3: 44949 | P3: 44949 | Q3: =B3/B3 -> 1 | R3: =((C3/B3)-1) -> 0
A4: Costo de Ventas [Cost of Goods Sold]
A5: Inventario Inicial de Productos Terminados (Inicial) | B5: 7502.88 | C5: 7502.88 | D5: 7502.88 | E5: 7502.88 | F5: 7502.88 | G5: 7502.88 | H5: 7502.88 | I5: 7502.88 | J5: 7502.88 | K5: 7502.88 | L5: 7502.88 | M5: 7502.88 | N5: 7502.88 | O5: 7502.88 | P5: 7502.88 | Q5: =B5/$B$3 -> 0.16691984 | R5: =((C5/B5)-1) -> 0
A6: Costo de los Productos Manufacturados (Materia Prima + Gas, Luz y Agua) | B6: =B36 -> 30434.22 | C6: =B36 -> 30434.22 | D6: =B36 -> 30434.22 | E6: =B36 -> 30434.22 | F6: =B36 -> 30434.22 | G6: =B36 -> 30434.22 | H6: =B36 -> 30434.22 | I6: =B36 -> 30434.22 | J6: =B36 -> 30434.22 | K6: =B36 -> 30434.22 | L6: =B36 -> 30434.22 | M6: =B36 -> 30434.22 | N6: =B36 -> 30434.22 | O6: =B36 -> 30434.22 | P6: =B36 -> 30434.22 | Q6: =B6/$B$3 -> 0.67708336 | R6: =((C6/B6)-1) -> 0
A7: Costo de los Productos Disponibles para la Venta | B7: =SUM(B5:B6) -> 37937.1 | C7: =SUM(C5:C6) -> 37937.1 | D7: =SUM(D5:D6) -> 37937.1 | E7: =SUM(E5:E6) -> 37937.1 | F7: =SUM(F5:F6) -> 37937.1 | G7: =SUM(G5:G6) -> 37937.1 | H7: =SUM(H5:H6) -> 37937.1 | I7: =SUM(I5:I6) -> 37937.1 | ... O7: =SUM(O5:O6) -> 37937.1 | P7: =(P5+P6) -> 37937.1 | Q7: =B7/$B$3 -> 0.8440032 | R7: =((C7/B7)-1) -> 0
A8: Inventario Final de Productos Terminados (Un mes Despues) | B8: 0 | C8: 7502.88 | D8: 7502.88 | E8: 7502.88 | F8: 7502.88 | G8: 7502.88 | H8: 7502.88 | I8: 7502.88 | J8: 7502.88 | K8: 7502.88 | L8: 7502.88 | M8: 7502.88 | N8: 7502.88 | O8: 7502.88 | P8: 7502.88 | Q8: =B8/$B$3 -> 0
A9: Costo de los Productos Vendidos | B9: =B7-B8 -> 37937.1 | C9: =C7-C8 -> 30434.22 | D9: =D7-D8 -> 30434.22 | E9: =E7-E8 -> 30434.22 | F9: =F7-F8 -> 30434.22 | G9: =G7-G8 -> 30434.22 | H9: =H7-H8 -> 30434.22 | I9: =I7-I8 -> 30434.22 | ... P9: =P7-P8 -> 30434.22 | Q9: =B9/$B$3 -> 0.8440032 | R9: =((C9/B9)-1) -> -0.19777157
A10: Utilidad Bruta [Gross Margin] | B10: =B3-B9 -> 7011.9 | C10: =C3-C9 -> 14514.78 | D10: =D3-D9 -> 14514.78 | E10: =E3-E9 -> 14514.78 | F10: =F3-F9 -> 14514.78 | G10: =G3-G9 -> 14514.78 | H10: =H3-H9 -> 14514.78 | I10: =I3-I9 -> 14514.78 | ... P10: =P3-P9 -> 14514.78 | Q10: =B10/$B$3 -> 0.1559968 | R10: =((C10/B10)-1) -> 1.070021
A12: Gastos de Venta y Marketing [Sales & Marketing](Activo Fijo) | B12: 60770.28 | C12: 3506.64 | D12: 8132.82 | E12: 12759 | F12: 17385.18 | G12: 22011.36 | H12: 26637.54 | I12: 31263.72 | J12: 35889.9 | K12: 40516.08 | L12: 45142.26 | M12: 49768.44 | N12: 54394.62 | O12: 59020.8 | P12: 63646.98 | Q12: =B12/$B$3 -> 1.3519829 | R12: =((C12/B12)+1) -> 1.0577032
A13: Gastos de Investigacion y Desarrollo [Research and Development] | B13: 0 | C13: 0 | D13: 0 | E13: 0 | F13: 0 | G13: 0 | H13: 0 | I13: 0 | J13: 0 | K13: 0 | L13: 0 | M13: 0 | N13: 0 | O13: 0 | P13: 0 | Q13: =B13/$B$3 -> 0
A14: Gastos de Administracion [General & Administrative](Rentas y Salarios) | B14: 9888.6 | C14: 9888.6 | D14: 9888.6 | E14: 9888.6 | F14: 9888.6 | G14: 9888.6 | H14: 9888.6 | I14: 9888.6 | J14: 9888.6 | K14: 9888.6 | L14: 9888.6 | M14: 9888.6 | N14: 9888.6 | O14: 9888.6 | P14: 9888.6 | Q14: =B14/$B$3 -> 0.219996 | R14: =((C14/B14)+1) -> 2
A15: Gastos de Operación | B15: =SUM(B12:B14) -> 70658.88 | C15: =SUM(C12:C14) -> 13395.24 | D15: =SUM(D12:D14) -> 18021.42 | E15: =SUM(E12:E14) -> 22647.6 | F15: =SUM(F12:F14) -> 27273.78 | G15: =SUM(G12:G14) -> 31899.96 | H15: =SUM(H12:H14) -> 36526.14 | I15: =SUM(I12:I14) -> 41152.32 | ... P15: =SUM(P12:P14) -> 73535.58 | Q15: =B15/$B$3 -> 1.5719789 | R15: =((C15/B15)+1) -> 1.1895762
A16: Utilidad de Operación [Income from Operations] | B16: =B10-B15 -> -63646.98 | C16: =C10-C15 -> 1119.54 | D16: =D10-D15 -> -3506.64 | E16: =E10-E15 -> -8132.82 | F16: =F10-F15 -> -12759 | G16: =G10-G15 -> -17385.18 | H16: =H10-H15 -> -22011.36 | I16: =I10-I15 -> -26637.54 | ... P16: =P10-P15 -> -59020.8 | Q16: =B16/$B$3 -> -1.4159821 | R16: =((C16/B16)+1) -> 0.98241016
A18: Impuestos a la Utilidad[Income Taxes] | B18: 0 | C18: 0 | D18: 0 | E18: 0 | F18: 0 | G18: 0 | H18: 0 | I18: 0 | J18: 0 | K18: 0 | L18: 0 | M18: 0 | N18: 0 | O18: 0 | P18: 0 | Q18: =B18/$B$3 -> 0
A20: Utilidad Neta [Net Income] | B20: =B16-B18 -> -63646.98 | C20: =C16-C18 -> 1119.54 | D20: =D16-D18 -> -3506.64 | E20: =E16-E18 -> -8132.82 | F20: =F16-F18 -> -12759 | G20: =G16-G18 -> -17385.18 | H20: =H16-H18 -> -22011.36 | I20: =I16-I18 -> -26637.54 | ... P20: =P16-P18 -> -59020.8 | Q20: =B20/$B$3 -> -1.4159821 | R20: =((C20/B20)+1) -> 0.98241016
A22: COSTO DE LOS PRODUCTOS MANUFACTURADOS | B22: INICIAL
A23: Materiales Directos:
A24: Inventario Inicial | B24: 0
A25: Compras de Materiales Directos (Materia Prima) | B25: 27434.22
A26: Costo de Materiales Directos Disponibles para su Uso | B26: =SUM(B24:B25) -> 27434.22
A27: Inventario Final | B27: 0
A28: Materiales Directos Usados | B28: =B26-B27 -> 27434.22
A29: Mano de Obra Directa | B29: 0
A30: Costos Indirectos de Manufactura:
A31: Mano de Obra Indirecta
A32: Suministros
A33: Gas, Luz y Agua | B33: 3000
A34: Depreciacion de Equipo | B34: 0
A35: Total de Costos Indirectos de Manufactura | B35: =SUM(B31:B34) -> 3000
A36: Costo de los Productos Manufacturados | B36: =SUM(B28,B29,B35) -> 30434.22
